Workbook

Sheet Executive
A1: VEGO-AI Iris Requirements — Canonical Execution Control
A3: Evidence-honest baseline: canonical work, control, experiment, role, and schedule denominators are visible; human and external gates remain open.
A5: Baseline Metric | B5: Current Value | D5: Canonical WP Status | E5: Count | G5: Immediate Critical Path
A6: Control rows | B6: =COUNTA(Control_Acceptance!$A$4:$A$200) -> 44 | D6: blocked | E6: =COUNTIF(Work_Packages!$H$4:$H$32,D6) -> 18 | G6: 1 | H6: Reconcile overdue canonical source/provenance gate | I6: partial | J6: WP-001 | K6: Human review pending
A7: Closure-eligible controls | B7: =COUNTIF(Control_Acceptance!$P$4:$P$200,"YES")&"/"&COUNTA(Control_Acceptance!$A$4:$A$200) -> 0/44 | D7: partial | E7: =COUNTIF(Work_Packages!$H$4:$H$32,D7) -> 6 | G7: 2 | H7: Complete two independent bilingual reviews | I7: blocked | J7: WP-002 | K7: 0/1,195 per reviewer
A8: Supervisor decisions | B8: =COUNTIF(Decision_Log!$D$4:$D$13,"<>Pending")&"/10" -> 0/10 | D8: planned | E8: =COUNTIF(Work_Packages!$H$4:$H$32,D8) -> 5 | G8: 3 | H8: Rehearse exact presentation | I8: blocked | J8: WP-005 | K8: Human rehearsal not run
A9: Transcript dual review | B9: 0/1,195 | D9: evidence_ready | E9: =COUNTIF(Work_Packages!$H$4:$H$32,D9) -> 0 | G9: 4 | H9: Approve/deliver/access-test exact package | I9: blocked | J9: WP-006 | K9: Not shared or tested
A10: EXP-005 safe labels | B10: 0/24 | D10: accepted/final | E10: =SUM(COUNTIF(Work_Packages!$H$4:$H$32,{"accepted","accepted_ongoing","accepted_after_correction","superseded_approved","not_applicable_approved"})) -> 0 | G10: 5 | H10: Obtain August 5 decisions | I10: planned | J10: WP-007 | K10: 0/10 outcomes
A11: Medical readiness | B11: =COUNTIF(Medical_Gates!$G$4:$G$9,"PASS")&"/6" -> 0/6 | G11: 6 | H11: Execute first literature tranche | I11: partial | J11: WP-009 | K11: Protocol ready; not run
A12: Recipient access tests | B12: 0/2 | G12: 7 | H12: Keep medicine NO-GO unless G1–G6 pass | I12: blocked | J12: WP-018 | K12: 0/6
A13: Experiment IDs visible | B13: 26/26 (10 IRIS + 10 canonical + 6 SCI)
A14: Canonical roles visible | B14: =COUNTA(Role_Assignments!$A$4:$A$22)&"/19" -> 19/19
A16: Do not claim completion: structure can pass while readiness and closure remain non-zero until real human/external evidence exists.
A18: Workbook as-of (dynamic) | B18: =NOW() -> 46237.461

Sheet Work_Packages
A1: VEGO-AI Iris Requirements — Canonical Work Packages
A2: Direct view of WP-001 through WP-029 from the canonical JSON board; no aggregate WP namespace remains.
A3: WP_ID | B3: Work Package | C3: Phase | D3: Owner Roles | E3: Due (local) | F3: Timezone | G3: Dependencies | H3: Status | I3: Overdue | J3: Controls | K3: IRIS Experiments | L3: Canonical Experiments | M3: Deliverables | N3: Acceptance Checks | O3: Evidence | P3: Gates
A4: WP-001 | B4: Reconcile sources, hashes, segment coverage, and provenance | C4: Aug 1-2 evidence reconciliation | D4: ALI | E4: 46236.5 | F4: Asia/Jerusalem | G4: None | H4: partial | I4: =IF(OR(H4="accepted",H4="accepted_ongoing",H4="accepted_after_correction",H4="superseded_approved",H4="not_applicable_approved"),"CLOSED",IF(E4<NOW(),"OVERDUE","ON TRACK")) -> OVERDUE | J4: R-11, R-12, A-05, A-08, Q-05 | K4: IRIS-EXP-01, IRIS-EXP-05, IRIS-EXP-07 | L4: None | M4: DEL-WP001-01: 1,195-row preliminary disposition ledger | DEL-WP001-02: Current source and derived provenance manifest | N4: AC-WP001-01 [pending]: All 1,195 segment IDs and the 46:26.283 timeline are represented without unexplained gaps | AC-WP001-02 [pending]: Raw-source and tracked derived hashes are current and historical registers are identified as snapshots | O4: EV-WP001-01 [present_unverified] docs/research/meetings/2026-07-29-iris-zoom-preliminary-disposition.json | EV-WP001-02 [present_unverified] docs/research/meetings/2026-07-29-iris-supervisor-provenance-manifest.md | P4: GATE-WP001-01 [pending] Ali reviews the reconciled machine baseline
A5: WP-002 | B5: Dual-review and adjudicate the complete bilingual Zoom record | C5: Aug 1-3 bilingual review | D5: ALI, ZOOM_REVIEWER_B, ZOOM_ADJUDICATOR, IRIS, ARNON | E5: 46237.75 | F5: Asia/Jerusalem | G5: WP-001 | H5: blocked | I5: =IF(OR(H5="accepted",H5="accepted_ongoing",H5="accepted_after_correction",H5="superseded_approved",H5="not_applicable_approved"),"CLOSED",IF(E5<NOW(),"OVERDUE","ON TRACK")) -> ON TRACK | J5: None | K5: IRIS-EXP-06 | L5: None | M5: DEL-WP002-01: Dual-reviewed and adjudicated 1,195-row ledger | DEL-WP002-02: Full-media review records for both reviewers | N5: AC-WP002-01 [pending]: 1,195 of 1,195 segments are independently reviewed and every disagreement is adjudicated | AC-WP002-02 [pending]: Zero uncategorized segments, zero orphan substantive clauses, and all named quotations have confirmed attribution | O5: EV-WP002-01 [pending] docs/research/meetings/2026-07-29-iris-zoom-adjudicated-ledger.json | EV-WP002-02 [pending] docs/research/meetings/2026-07-29-iris-zoom-full-media-review.json | P5: GATE-WP002-01 [pending] Independent Reviewer B and bilingual adjudicator complete their work | GATE-WP002-02 [pending] Iris or Arnon confirms any disputed attribution assigned to them
A6: WP-003 | B6: Regenerate the bilingual transcript, call report, and R-A-Q registers | C6: Aug 3-4 adjudicated package | D6: ALI | E6: 46238.417 | F6: Asia/Jerusalem | G6: WP-002 | H6: blocked | I6: =IF(OR(H6="accepted",H6="accepted_ongoing",H6="accepted_after_correction",H6="superseded_approved",H6="not_applicable_approved"),"CLOSED",IF(E6<NOW(),"OVERDUE","ON TRACK")) -> ON TRACK | J6: None | K6: IRIS-EXP-06 | L6: None | M6: DEL-WP003-01: Adjudicated bilingual transcript and full call report | DEL-WP003-02: Regenerated requirements, actions, questions, and provenance | N6: AC-WP003-01 [pending]: Every substantive clause maps to a stable control or an explicit non-control classification | AC-WP003-02 [pending]: No direct quotation or certain named attribution relies on machine-only evidence | O6: EV-WP003-01 [pending] docs/research/meetings/2026-07-29-iris-supervisor-call-report.adjudicated.md | EV-WP003-02 [pending] docs/research/meetings/2026-07-29-iris-adjudicated-control-register.json | P6: GATE-WP003-01 [pending] The adjudicated ledger is complete and released for derivation
A7: WP-004 | B7: Build the August 5 supervisor presentation package | C7: Aug 2-4 supervisor package | D7: ALI | E7: 46238.5 | F7: Asia/Jerusalem | G7: WP-001 | H7: partial | I7: =IF(OR(H7="accepted",H7="accepted_ongoing",H7="accepted_after_correction",H7="superseded_approved",H7="not_applicable_approved"),"CLOSED",IF(E7<NOW(),"OVERDUE","ON TRACK")) -> ON TRACK | J7: None | K7: IRIS-EXP-01, IRIS-EXP-08 | L7: None | M7: DEL-WP004-01: English 12-slide PPTX | DEL-WP004-02: Matching PDF | DEL-WP004-03: Notes, bilingual evidence appendix, decision worksheet, and control manifest | N7: AC-WP004-01 [pending]: Exactly 12 core slides fit an 11-minute delivery and all controls are reachable in core or appendix | AC-WP004-02 [pending]: 0/24 labels, 0/6 medical gates, and 25/26 MIMIC tables remain visible with correct claim boundaries | O7: EV-WP004-01 [verified] presentations/VEGO-AI-Iris-Supervisor-Decisions-2026-08-05.pptx | EV-WP004-02 [verified] presentations/VEGO-AI-Iris-Supervisor-Decisions-2026-08-05.pdf | EV-WP004-03 [present_unverified] docs/research/meetings/2026-08-05-supervisor-presentation-manifest.md | P7: GATE-WP004-01 [pending] Ali approves the exact content and evidence boundaries
A8: WP-005 | B8: Render, inspect, and rehearse the exact presentation | C8: Aug 4 presentation assurance | D8: ALI, IRIS_ROLE_REVIEWER, ARNON_ROLE_REVIEWER, REHEARSAL_RECORDER | E8: 46238.625 | F8: Asia/Jerusalem | G8: WP-004 | H8: blocked | I8: =IF(OR(H8="accepted",H8="accepted_ongoing",H8="accepted_after_correction",H8="superseded_approved",H8="not_applicable_approved"),"CLOSED",IF(E8<NOW(),"OVERDUE","ON TRACK")) -> ON TRACK | J8: None | K8: IRIS-EXP-02, IRIS-EXP-08 | L8: None | M8: DEL-WP005-01: Rendered-slide and visual-QA evidence bound to the current PPTX/PDF hashes | DEL-WP005-02: Timed and adversarial rehearsal record | N8: AC-WP005-01 [pending]: Fonts, overflow, contrast, tables, citations, Hebrew RTL, notes, PPTX, PDF, screen sharing, and offline backup pass | AC-WP005-02 [pending]: One timed rehearsal and one adversarial Q-and-A rehearsal are completed by four distinct roles | O8: EV-WP005-01 [verified] docs/research/meetings/2026-08-05-supervisor-rehearsal-record.md | EV-WP005-02 [present_unverified] docs/research/meetings/2026-08-05-supervisor-rehearsal-record.md | P8: GATE-WP005-01 [pending] Presenter, two adversarial role reviewers, and recorder complete the rehearsal
A9: WP-006 | B9: Approve, deliver, and access-test the exact supervisor package | C9: Aug 4 controlled delivery | D9: ALI, IRIS, ARNON | E9: 46238.75 | F9: Asia/Jerusalem | G9: WP-004, WP-005 | H9: blocked | I9: =IF(OR(H9="accepted",H9="accepted_ongoing",H9="accepted_after_correction",H9="superseded_approved",H9="not_applicable_approved"),"CLOSED",IF(E9<NOW(),"OVERDUE","ON TRACK")) -> ON TRACK | J9: R-17, A-04, A-05, Q-07 | K9: IRIS-EXP-08 | L9: None | M9: DEL-WP006-01: Hash-bound local backup and delivery/access record | N9: AC-WP006-01 [pending]: Ali reviews the exact delivered version before sharing | AC-WP006-02 [pending]: Iris and Arnon independently pass access tests and delivery metadata records version, hash, permissions, and time | O9: EV-WP006-01 [present_unverified] docs/research/meetings/2026-08-05-supervisor-delivery-access-record.md | P9: GATE-WP006-01 [pending] Ali approves the exact package | GATE-WP006-02 [pending] Both supervisors independently verify recipient access
A10: WP-007 | B10: Obtain and read back August 5 supervisor decisions | C10: Aug 5 meeting | D10: ALI, IRIS, ARNON | E10: 46239.417 | F10: Asia/Jerusalem | G10: WP-006 | H10: planned | I10: =IF(OR(H10="accepted",H10="accepted_ongoing",H10="accepted_after_correction",H10="superseded_approved",H10="not_applicable_approved"),"CLOSED",IF(E10<NOW(),"OVERDUE","ON TRACK")) -> ON TRACK | J10: R-01, R-02, R-03, R-04, R-13, A-01, A-06, Q-01, Q-07, Q-10 | K10: IRIS-EXP-09 | L10: None | M10: DEL-WP007-01: D-RQ-01 through D-RQ-10 outcomes and exact read-back | DEL-WP007-02: Exactly one primary next task with definition of done | N10: AC-WP007-01 [pending]: Mandatory D-RQ-01 through 05 and D-RQ-07 receive explicit outcomes; silence remains Deferred | AC-WP007-02 [pending]: RQ wording, Plan A-B, claim boundaries, owners, due dates, and one next task are read back | O10: EV-WP007-01 [pending] docs/research/phd-proposal/decision-change-log.md | EV-WP007-02 [pending] docs/research/meetings/2026-08-05-supervisor-minutes.md | P10: GATE-WP007-01 [pending] Iris and Arnon explicitly disposition the requested decisions
A11: WP-008 | B11: Issue minutes and propagate decisions within 24 hours | C11: Aug 6 closeout | D11: ALI, IRIS, ARNON | E11: 46240.417 | F11: Asia/Jerusalem | G11: WP-007 | H11: blocked | I11: =IF(OR(H11="accepted",H11="accepted_ongoing",H11="accepted_after_correction",H11="superseded_approved",H11="not_applicable_approved"),"CLOSED",IF(E11<NOW(),"OVERDUE","ON TRACK")) -> ON TRACK | J11: R-06, R-13, A-07 | K11: IRIS-EXP-04, IRIS-EXP-09 | L11: None | M11: DEL-WP008-01: Bilingual evidence-linked minutes and written confirmation record | DEL-WP008-02: Propagation and stale-wording audit | N11: AC-WP008-01 [pending]: Written confirmation or correction is obtained and every affected artifact is updated without silent deletion | AC-WP008-02 [pending]: Structure and readiness validators are rerun on the exact archived package | O11: EV-WP008-01 [pending] docs/research/meetings/2026-08-05-supervisor-minutes.md | EV-WP008-02 [pending] docs/research/phd-proposal/decision-change-log.md | P11: GATE-WP008-01 [pending] Supervisors confirm or correct the minutes in writing
A12: WP-009 | B12: Execute and log the first literature searches and screening pass | C12: Aug 6-12 literature execution | D12: ALI | E12: 46246.75 | F12: Asia/Jerusalem | G12: WP-007 | H12: partial | I12: =IF(OR(H12="accepted",H12="accepted_ongoing",H12="accepted_after_correction",H12="superseded_approved",H12="not_applicable_approved"),"CLOSED",IF(E12<NOW(),"OVERDUE","ON TRACK")) -> ON TRACK | J12: R-14, R-15, R-16, A-02, A-03, Q-04 | K12: None | L12: None | M12: DEL-WP009-01: Executed search log, deduplication, screening, and verified seed identities | N12: AC-WP009-01 [pending]: Queries, databases, dates, deduplication, inclusion, exclusion, and quality decisions are reproducible | O12: EV-WP009-01 [pending] docs/research/phd-proposal/literature-execution-log.json | P12: GATE-WP009-01 [pending] Ali verifies paper identities and authors-versus-researcher separation
A13: WP-010 | B13: Deliver proposal v0.2, Clalit brief, Penina map, and process inquiries | C13: Aug 6-12 proposal and dependencies | D13: ALI, GRADUATE_COORDINATOR, CLINICAL_OWNER | E13: 46246.75 | F13: Asia/Jerusalem | G13: WP-007 | H13: partial | I13: =IF(OR(H13="accepted",H13="accepted_ongoing",H13="accepted_after_correction",H13="superseded_approved",H13="not_applicable_approved"),"CLOSED",IF(E13<NOW(),"OVERDUE","ON TRACK")) -> ON TRACK | J13: R-05, R-17, R-18, R-19, A-04, A-14, A-15, Q-08, Q-09, Q-10 | K13: None | L13: None | M13: DEL-WP010-01: Proposal v0.2 | DEL-WP010-02: Completed Clalit research request | DEL-WP010-03: Penina and university-process response record | DEL-WP010-04: Current proposal v0.2 working draft recorded as partial writing evidence only | N13: AC-WP010-01 [pending]: Proposal v0.2 includes approved-or-clearly-pending RQs, studies, methods, resources, risks, and claim boundaries | AC-WP010-02 [pending]: External dates, requirements, availability, and access claims are verified or explicitly marked unverified | O13: EV-WP010-01 [pending] docs/research/phd-proposal/proposal-v0.2.md | EV-WP010-02 [pending] docs/research/governance/clalit-research-request.md | EV-WP010-03 [pending] docs/research/phd-proposal/external-process-response-register.json | EV-WP010-04 [verified] docs/research/phd-proposal/proposal-v0.2-working-draft.md | P13: GATE-WP010-01 [pending] Authorized university and course contacts provide written responses
A14: WP-011 | B14: Freeze the human-evidence protocol and supervisor decisions | C14: Aug 5-6 scientific governance | D14: ALI, IRIS, ARNON, METHODS_REVIEWER | E14: 46240.75 | F14: Asia/Jerusalem | G14: WP-007 | H14: blocked | I14: =IF(OR(H14="accepted",H14="accepted_ongoing",H14="accepted_after_correction",H14="superseded_approved",H14="not_applicable_approved"),"CLOSED",IF(E14<NOW(),"OVERDUE","ON TRACK")) -> ON TRACK | J14: None | K14: None | L14: EXP-005, EXP-019, EXP-020 | M14: DEL-WP011-01: D-E01 through D-E07 explicit outcomes | DEL-WP011-02: Approved preregistration and any canonical amendments for SCI-EXP gaps | N14: AC-WP011-01 [pending]: Vocabulary, consent, thresholds, policy gate, one-time holdout, formal claim rule, and effort-study scope are explicit | AC-WP011-02 [pending]: The four-arm, full reuse-matrix, and longitudinal additions are approved amendments or remain visibly blocked | O14: EV-WP011-01 [pending] docs/research/thesis-evidence/SUPERVISOR_EVIDENCE_DECISIONS.md | EV-WP011-02 [pending] docs/research/thesis-evidence/PREREGISTRATION_EXP019_027.md | P14: GATE-WP011-01 [pending] Iris and Arnon approve or correct the scientific protocol | GATE-WP011-02 [pending] Applicable ethics and participant-handling requirements are confirmed
A15: WP-012 | B15: Run EXP-019 independent reviewer calibration | C15: Aug 6-12 human calibration | D15: DOMAIN_REVIEWER_1, DOMAIN_REVIEWER_2, LABEL_ADJUDICATOR | E15: 46246.75 | F15: Asia/Jerusalem | G15: WP-011 | H15: blocked | I15: =IF(OR(H15="accepted",H15="accepted_ongoing",H15="accepted_after_correction",H15="superseded_approved",H15="not_applicable_approved"),"CLOSED",IF(E15<NOW(),"OVERDUE","ON TRACK")) -> ON TRACK | J15: None | K15: None | L15: EXP-019 | M15: DEL-WP012-01: Two immutable three-row calibration returns and pair report | DEL-WP012-02: Human-frozen instruction manifest and EXP-020 go-defer decision | N15: AC-WP012-01 [pending]: Two distinct eligible humans complete all three excluded rows and both return hashes are frozen | AC-WP012-02 [pending]: Calibration remains generalization-unsafe and transfers no label into evaluation | O15: EV-WP012-01 [pending] reports/generated/independent_evidence_v1/validation/calibration/calibration_pair_report.json | EV-WP012-02 [pending] reports/generated/independent_evidence_v1/validation/calibration/calibration_instruction_freeze.json | P15: GATE-WP012-01 [pending] Two independent reviewers provide valid calibration returns
... A32: WP-029 | B32: Close authorized submission and issue the closure certificate | C32: Oct 7 submission or approval buffer | D32: ALI, IRIS, ARNON, GRADUATE_COORDINATOR | E32: 46302.75 | F32: Asia/Jerusalem | G32: WP-028 | H32: blocked | I32: =IF(OR(H32="accepted",H32="accepted_ongoing",H32="accepted_after_correction",H32="superseded_approved",H32="not_applicable_approved"),"CLOSED",IF(E32<NOW(),"OVERDUE","ON TRACK")) -> ON TRACK | J32: A-13 | K32: IRIS-EXP-10 | L32: None | M32: DEL-WP029-01: Verified authorized submission receipt bound to the exact package | DEL-WP029-02: Issued closure certificate with final denominator and allowed final states only | N32: AC-WP029-01 [pending]: The authorized route, package hash, external receipt, approval, and submission time are independently verifiable | AC-WP029-02 [pending]: Every discovered control is in an allowed final state and any new instruction invalidates an earlier certificate until resolved | O32: EV-WP029-01 [pending] docs/research/phd-proposal/authorized-submission-receipt.json | EV-WP029-02 [pending] docs/research/phd-proposal/iris-closure-certificate.json | P32: GATE-WP029-01 [pending] Iris and Arnon approve the exact final package and closure disposition | GATE-WP029-02 [pending] Authorized university route returns a verifiable receipt

Sheet Control_Acceptance
A1: Dynamic Control Acceptance — 19 Requirements / 15 Actions / 10 Questions
A2: Final state is Pending for all 44 baseline controls. New discovered controls must receive a stable ID and be appended; closure denominator then increases automatically.
A3: Control_ID | B3: Kind | C3: Type | D3: Control Item | E3: Source | F3: Owner | G3: Due/Gate | H3: Dependencies | I3: Deliverable/Evidence | J3: Acceptance Check | K3: Extraction | L3: Implementation | M3: Acceptance | N3: Final State | O3: Ongoing Control | P3: Closure Eligible | Q3: Canonical WPs | R3: Gate Note
A4: R-01 | B4: Requirement | C4: Requirement — proposal architecture | D4: Use one umbrella PhD question and exactly three related subquestions. | E4: REQ-29JUL/R-01; TRN-29JUL S-0001–S-0002, S-0258–S-0266, S-0537–S-0543, S-0657–S-0660 | F4: Ali; Iris and Arnon confirm | G4: Next supervisor checkpoint; calendar date unverified | H4: Q-01; A-01 | I4: Approved question block and three-study-contract.md | J4: One umbrella question and exactly SQ1–SQ3 appear consistently in the proposal and study contract; supervisor decision is logged. | K4: Machine-only; dual review pending | L4: Evidence ready | M4: Pending Iris/Arnon decision | N4: Pending | O4: 5 Aug checkpoint; Ali; exact wording plus decision log | P4: =IF(OR(N4="Accepted",N4="Accepted with ongoing control",N4="Accepted after correction",N4="Superseded by approved decision",N4="Not applicable by approved Plan B or other decision"),"YES","NO") -> NO | Q4: WP-007, WP-017 | R4: Exact working wording is synchronized but provisional until logged approval; do not retain competing five- or six-question sets as active.
A5: R-02 | B5: Requirement | C5: Requirement — study mapping | D5: Map each subquestion to a concrete study, method, evidence/data, and artifact. | E5: REQ-29JUL/R-02; TRN-29JUL S-0002–S-0004, S-0011–S-0013 | F5: Ali; supervisors approve | G5: Before proposal architecture is frozen | H5: R-01; Q-01; Q-03 | I5: three-study-contract.md and proposal study table | J5: Every SQ has method, data/evidence, artifact, metrics, contribution, dependencies, fallback, and publication target; no empty required field. | K5: Machine-only; dual review pending | L5: Evidence ready | M5: Pending Iris/Arnon decision | N5: Pending | O5: 5 Aug checkpoint; Ali; study-contract decision | P5: =IF(OR(N5="Accepted",N5="Accepted with ongoing control",N5="Accepted after correction",N5="Superseded by approved decision",N5="Not applicable by approved Plan B or other decision"),"YES","NO") -> NO | Q5: WP-007, WP-017 | R5: All study outcomes are Planned until executed; medical variants are partner-dependent.
A6: R-03 | B6: Requirement | C6: Requirement — proposal contents | D6: Include motivation, literature review, research questions, methodology/artifacts, preliminary results, and work plan/timeline. | E6: REQ-29JUL/R-03; TRN-29JUL S-0007–S-0018 | F6: Ali | G6: Developed September draft; exact date unverified | H6: R-01, R-02, R-04, R-08, R-18 | I6: Full proposal draft with six-section completeness checklist | J6: All six areas are present, cross-referenced, and traceable to claims, studies, and milestones. | K6: Machine-only; dual review pending | L6: Evidence ready | M6: Pending Iris/Arnon decision | N6: Pending | O6: Each proposal version; Ali; six-area completeness evidence | P6: =IF(OR(N6="Accepted",N6="Accepted with ongoing control",N6="Accepted after correction",N6="Superseded by approved decision",N6="Not applicable by approved Plan B or other decision"),"YES","NO") -> NO | Q6: WP-007, WP-017 | R6: Preliminary results must remain software/modeling evidence; medicine is not reported as achieved.
A7: R-04 | B7: Requirement | C7: Requirement — doctoral adequacy | D7: Demonstrate novelty, doctoral scale, literature positioning, feasibility, available skills/resources, and schedule credibility. | E7: REQ-29JUL/R-04; TRN-29JUL S-0027–S-0033 | F7: Ali; supervisors judge adequacy | G7: Proposal submission gate | H7: R-02, R-03, R-09, R-18; resource/RAID register | I7: Doctoral-adequacy section, contribution table, feasibility case, resource plan, and schedule | J7: Each adequacy dimension has evidence or a named mitigation; supervisors record accepted or accepted-with-changes. | K7: Machine-only; dual review pending | L7: Partial | M7: Pending Iris/Arnon adequacy review | N7: Pending | O7: Weekly proposal delta; Ali; novelty/scale/resource evidence | P7: =IF(OR(N7="Accepted",N7="Accepted with ongoing control",N7="Accepted after correction",N7="Superseded by approved decision",N7="Not applicable by approved Plan B or other decision"),"YES","NO") -> NO | Q7: WP-007, WP-026 | R7: Novelty is Preliminary until literature synthesis and supervisor review; feasibility cannot rely only on medicine.
A8: R-05 | B8: Requirement | C8: Requirement — candidacy presentation | D8: Prepare a short reviewer-orientation presentation focused on progress and questions, not a duplicate of the proposal. | E8: REQ-29JUL/R-05; TRN-29JUL S-0046–S-0052 | F8: Ali | G8: After candidacy process and date are formally confirmed | H8: A-14; Q-08; R-03 | I8: Concise candidacy deck and presenter notes | J8: Deck orients reviewers, summarizes progress/evidence boundaries, names decisions sought, and fits the verified time limit. | K8: Machine-only; dual review pending | L8: Not started — blocked | M8: Pending authoritative candidacy rules | N8: Pending | O8: On official-process response; A-14 owner; candidacy checklist | P8: =IF(OR(N8="Accepted",N8="Accepted with ongoing control",N8="Accepted after correction",N8="Superseded by approved decision",N8="Not applicable by approved Plan B or other decision"),"YES","NO") -> NO | Q8: WP-010, WP-026 | R8: Do not invent presentation duration, reviewer count, or committee rules.
A9: R-06 | B9: Requirement | C9: Requirement — parallel progress | D9: Continue writing and research while reviewer/committee logistics proceed. | E9: REQ-29JUL/R-06; TRN-29JUL S-0127–S-0149 | F9: Ali | G9: Weekly and ongoing | H9: R-13; A-07; A-14 | I9: Dated weekly pre-reads, proposal deltas, and completed artifacts | J9: Every week records completed evidence, one next task, blockers, and proposal text advanced even if administration is pending. | K9: Machine-only; dual review pending | L9: Partial | M9: Pending first accepted weekly cycle | N9: Pending | O9: Weekly; Ali; pre-read, proposal delta, and closeout record | P9: =IF(OR(N9="Accepted",N9="Accepted with ongoing control",N9="Accepted after correction",N9="Superseded by approved decision",N9="Not applicable by approved Plan B or other decision"),"YES","NO") -> NO | Q9: WP-008, WP-023 | R9: Administrative uncertainty is not a reason to suspend Plan B work.
A10: R-07 | B10: Requirement | C10: Requirement — domain neutrality | D10: Keep questions answerable in software/modeling; medicine is a conditional evaluation context. | E10: REQ-29JUL/R-07; TRN-29JUL S-0448–S-0475 | F10: Ali; supervisors confirm | G10: Next RQ draft and every later revision | H10: R-01, R-02, R-09, R-10 | I10: Domain-neutral question block and Plan A/Plan B mapping | J10: Each question can be answered by the non-medical baseline and has an optional medical instantiation without changing its scientific meaning. | K10: Machine-only; dual review pending | L10: Evidence ready | M10: Pending Iris/Arnon decision | N10: Pending | O10: Each RQ revision; Ali; Plan B answerability check | P10: =IF(OR(N10="Accepted",N10="Accepted with ongoing control",N10="Accepted after correction",N10="Superseded by approved decision",N10="Not applicable by approved Plan B or other decision"),"YES","NO") -> NO | Q10: WP-017, WP-019 | R10: No medicine-only doctorate; Plan B is the protected default.
A11: R-08 | B11: Requirement | C11: Requirement — evidence boundary | D11: Identify current results as software/modeling evidence; medical work remains feasibility or planned evaluation. | E11: REQ-29JUL/R-08; TRN-29JUL S-0436–S-0446 | F11: Ali; claim-register owner | G11: Before every proposal/report release | H11: Claim register; EXP-005 gate; Q-02, Q-05 | I11: Claim register, proposal preliminary-results table, release claim check | J11: Every result has a claim state and source; no clinical or medical performance statement appears without approved evidence. | K11: Machine-only; dual review pending | L11: Evidence ready | M11: Pending Iris/Arnon claim-boundary decision | N11: Pending | O11: Every release; Ali; claim register and evidence check | P11: =IF(OR(N11="Accepted",N11="Accepted with ongoing control",N11="Accepted after correction",N11="Superseded by approved decision",N11="Not applicable by approved Plan B or other decision"),"YES","NO") -> NO | Q11: WP-017, WP-025 | R11: EXP-005 remains 0/24; no accuracy/generalization or clinical-performance claim.
A12: R-09 | B12: Requirement | C12: Requirement — medical dependency risk | D12: Do not make feasibility depend solely on medical data, experts, signatures, permissions, or access. | E12: REQ-29JUL/R-09; TRN-29JUL S-0382–S-0389, S-0403–S-0408, S-0462–S-0475 | F12: Ali; Iris/Arnon; clinical and governance owners currently unfilled | G12: Before any medical commitment; fallback review by 2026-08-26 | H12: A-09, A-15; Q-02, Q-05, Q-09, Q-10 | I12: Medical readiness checklist, named owners, RAID entries, Plan B schedule | J12: All six entry gates G1–G6 have documented owners, evidence paths, and feasible completion dates by 2026-08-26; otherwise execution defaults to Plan B. All six must pass before row-level access is considered. | K12: Machine-only; dual review pending | L12: Partial | M12: Pending medical-route/fallback decision | N12: Pending | O12: 26 Aug gate; Ali/supervisors; G1–G6 scorecard | P12: =IF(OR(N12="Accepted",N12="Accepted with ongoing control",N12="Accepted after correction",N12="Superseded by approved decision",N12="Not applicable by approved Plan B or other decision"),"YES","NO") -> NO | Q12: WP-018, WP-019 | R12: Data alone is insufficient. Named clinicians, governance, and infrastructure are mandatory.
A13: R-10 | B13: Requirement | C13: Requirement — two-plan fallback | D13: Present Plan A and Plan B with dependencies, decision point, and fallback triggers. | E13: REQ-29JUL/R-10; TRN-29JUL S-1153–S-1169 | F13: Ali; supervisors confirm | G13: Next proposal iteration; decision checkpoint 2026-08-26 | H13: R-07, R-09; A-09, A-10; Q-02, Q-03 | I13: Proposal alternatives table, fallback rule, RAID decision record | J13: Both plans answer the same questions and preserve doctoral contribution; Plan B activates automatically if any G1–G6 gate lacks an owner, evidence path, or feasible completion date at the checkpoint. | K13: Machine-only; dual review pending | L13: Partial | M13: Pending Iris/Arnon decision | N13: Pending | O13: 5 Aug and 26 Aug; Ali; Plan A/B and fallback log | P13: =IF(OR(N13="Accepted",N13="Accepted with ongoing control",N13="Accepted after correction",N13="Superseded by approved decision",N13="Not applicable by approved Plan B or other decision"),"YES","NO") -> NO | Q13: WP-018, WP-019 | R13: Plan A is medical-enabled and partner-dependent; Plan B is the non-medical execution baseline.
A14: R-11 | B14: Requirement | C14: Requirement — time-boxed familiarization | D14: Inspect medical resources only enough to understand shape, gaps, and relevance; stop before deep medical study. | E14: REQ-29JUL/R-11; TRN-29JUL S-0740–S-0819 | F14: Ali | G14: Alongside next RQ draft; before 2026-08-26 decision | H14: A-08; Q-05; R-12, R-17 | I14: Bounded MIMIC/resource sanity-check note with start/stop time, inventory, unknowns, and no data analysis | J14: Note addresses schema/data shape, relevance, missing information, governance questions, and stop condition; no full download or clinical inference. | K14: Machine-only; dual review pending | L14: Partial | M14: Pending human audit review | N14: Pending | O14: 26 Aug gate; Ali; bounded metadata-audit record | P14: =IF(OR(N14="Accepted",N14="Accepted with ongoing control",N14="Accepted after correction",N14="Superseded by approved decision",N14="Not applicable by approved Plan B or other decision"),"YES","NO") -> NO | Q14: WP-001, WP-018 | R14: Familiarization does not select MIMIC or authorize use; no raw patient data enters the repo. The audit date/scope is evidenced, but a four-hour elapsed-time claim is not.
A15: R-12 | B15: Requirement | C15: Requirement — restricted-data and LLM compliance | D15: Keep restricted data in the VDI; use only approved local/offline models; preserve purpose-bound, non-transferable access. | E15: REQ-29JUL/R-12; TRN-29JUL S-0844–S-0890, S-0950–S-0955 | F15: Data controller/security owner unfilled; Ali documents; supervisors accountable for research scope | G15: Before any restricted-data experiment | H15: A-11; Q-05, Q-06, Q-09; ethics/privacy approval | I15: Approved data-flow/security note, access register, local-model approval, and proposal constraint statement | J15: Authorized owner confirms storage, access, model, logging, retention, and export rules; technical runbook passes review before execution. | K15: Machine-only; dual review pending | L15: Not started — blocked | M15: Pending authorized data/security owner | N15: Pending | O15: Before any restricted work; owner unfilled; approved data-flow evidence | P15: =IF(OR(N15="Accepted",N15="Accepted with ongoing control",N15="Accepted after correction",N15="Superseded by approved decision",N15="Not applicable by approved Plan B or other decision"),"YES","NO") -> NO | Q15: WP-001, WP-018 | R15: Meeting statements are not an independently verified Clalit policy; fail closed until written approval.
... A47: Q-10 | B47: Open question | C47: Open question — partner status | D47: Was the proposed Clalit meeting accepted, and what are the retrieval mechanism and second partner? | E47: ACT-29JUL/Q-10 | F47: Iris/team | G47: Before treating opportunity as committed | H47: A-15; Q-02, Q-09 | I47: Confirmed invitation/minutes and partner/mechanism record | J47: Meeting status, identities, roles, mechanism meaning, decisions, and next steps are documented by an accountable participant. | K47: Machine-only; dual review pending | L47: Not started — blocked | M47: Pending accountable partner clarification | N47: Pending | O47: On partner response; Iris/team; invitation/minutes/mechanism record | P47: =IF(OR(N47="Accepted",N47="Accepted with ongoing control",N47="Accepted after correction",N47="Superseded by approved decision",N47="Not applicable by approved Plan B or other decision"),"YES","NO") -> NO | Q47: WP-007, WP-010 | R47: Unclear transcript terminology must be human-corrected before use.

Sheet Experiment_Crosswalk
A1: Experiment Coverage and Crosswalk
A2: All 10 IRIS assurance experiments, 10 canonical execution experiments, and 6 SCI proposal aliases are explicit; SCI aliases never create a second result set.
A3: Layer | B3: Experiment_ID | C3: Name | D3: Current Evidence State | E3: Mapped WPs | F3: Canonical/Related Mapping | G3: Locator | H3: Claim Boundary
A4: Assurance | B4: IRIS-EXP-01 | C4: Requirements traceability conformance | D4: PASS on 2026-07-30: 44/44 controls and locators; audited readiness distribution preserved | E4: WP-001, WP-004 | F4: Governed by IRIS assurance protocol | G4: ../../../experiments/IRIS-EXP-01-requirements-traceability-conformance/README.md | H4: Structural coverage is not substantive completion, human transcript confirmation, or supervisor approval.
A5: Assurance | B5: IRIS-EXP-02 | C5: Supervisor presentation and decision rehearsal | D5: Automated/local package preflight PASS on 2026-08-01; live timed and adversarial human rehearsals NOT RUN | E5: WP-005 | F5: Governed by IRIS assurance protocol | G5: ../../../experiments/IRIS-EXP-02-supervisor-presentation-decision-rehearsal/README.md | H5: Rehearsal readiness is not a real decision or approval by Iris or Arnon.
A6: Assurance | B6: IRIS-EXP-03 | C6: Claim-language and evidence-boundary audit | D6: PASS on 2026-07-30: canonical wording and high-risk boundary checks pass | E6: WP-017, WP-024 | F6: Governed by IRIS assurance protocol | G6: ../../../experiments/IRIS-EXP-03-claim-language-evidence-boundary-audit/README.md | H6: Language consistency does not independently validate evidence truth or quality.
A7: Assurance | B7: IRIS-EXP-04 | C7: Weekly commitment closure and change propagation | D7: Structural preflight PASS on 2026-07-30; first real weekly cycle NOT RUN | E7: WP-008 | F7: Governed by IRIS assurance protocol | G7: ../../../experiments/IRIS-EXP-04-weekly-commitment-closure-change-propagation/README.md | H7: Process conformance is not scientific validation or inferred supervisor acceptance.
A8: Assurance | B8: IRIS-EXP-05 | C8: Media-to-transcript coverage | D8: Structural PASS on 2026-08-01; full-media human review pending | E8: WP-001 | F8: Governed by IRIS assurance protocol | G8: ../../../experiments/IRIS-EXP-05-media-transcript-coverage/README.md | H8: Machine-level coverage does not establish transcription accuracy, speaker identity, or supervisor intent.
A9: Assurance | B9: IRIS-EXP-06 | C9: Bilingual meaning and speaker assurance | D9: Structural PASS on 2026-08-01; two independent reviews and adjudication NOT RUN | E9: WP-002, WP-003 | F9: Governed by IRIS assurance protocol | G9: ../../../experiments/IRIS-EXP-06-bilingual-meaning-speaker-assurance/README.md | H9: Reviewed meaning is not substantive approval, external-fact verification, or task completion.
A10: Assurance | B10: IRIS-EXP-07 | C10: Canonical status and provenance consistency | D10: Structural PASS on 2026-08-01 for the preliminary ledger; broader human truth remains pending | E10: WP-001 | F10: Governed by IRIS assurance protocol | G10: ../../../experiments/IRIS-EXP-07-canonical-status-provenance-consistency/README.md | H10: Record consistency does not prove scientific quality or create human acceptance.
A11: Assurance | B11: IRIS-EXP-08 | C11: Presentation and delivery assurance | D11: Structural/local artifact PASS on 2026-08-01; human rehearsal, Ali approval, delivery, and access evidence pending; NOT SHARED | E11: WP-004, WP-005, WP-006 | F11: Governed by IRIS assurance protocol | G11: ../../../experiments/IRIS-EXP-08-presentation-delivery-assurance/README.md | H11: Package and delivery readiness are not meeting attendance or supervisor approval.
A12: Assurance | B12: IRIS-EXP-09 | C12: Supervisor acceptance and propagation | D12: Structural PASS on 2026-08-01; real supervisor outcomes pending | E12: WP-007, WP-008 | F12: Governed by IRIS assurance protocol | G12: ../../../experiments/IRIS-EXP-09-supervisor-acceptance-propagation/README.md | H12: A passing process audit does not mean every control was accepted; final row states remain authoritative.
A13: Assurance | B13: IRIS-EXP-10 | C13: Final closure certificate | D13: Structural PASS on 2026-08-01; NOT ELIGIBLE and certificate NOT ISSUED | E13: WP-029 | F13: Governed by IRIS assurance protocol | G13: ../../../experiments/IRIS-EXP-10-final-closure-certificate/README.md | H13: A certificate is bounded to its evidence/revision and cannot authorize medical work or prove more than the cited evidence.
A14: Canonical scientific | B14: EXP-005 | C14: real label accuracy gate | D14: WP-011:blocked; WP-013:blocked | E14: WP-011, WP-013 | F14: EXP-005 | G14: experiments/EXP-005-real-label-accuracy-gate/README.md | H14: No result claim before the canonical protocol, human gates, and claim-state checks pass.
... A29: Proposal alias | B29: SCI-EXP-06 | C29: Ablation and usability | D29: Proposal/human-gated except for existing offline safety and operational evidence. No component-necessity, usability, decision-value, or effort conclusion exists yet. | E29: See canonical mapping | F29: Primary ablation anchor: EXP-027. Human-effort and interface anchors: EXP-026, EXP-031, and EXP-032. Safety/operational context: EXP-035 and EXP-036. | G29: docs/research/phd-proposal/scientific-experiment-crosswalk.md | H29: Alias has no independent result state.

Sheet Role_Assignments
A1: All 19 Canonical Human, External, and Tool Roles
A2: Roles are copied from the canonical board. Unfilled roles remain explicit blockers; data, ethics, VDI, and methods roles are not bundled.
A3: Role_ID | B3: Role | C3: Kind | D3: Current Assignee | E3: Filled | F3: Status | G3: Gate Bindings | H3: Evidence Required | I3: Fail-Closed Consequence
A4: ALI | B4: Program lead and proposal author | C4: internal_human | D4: Ali | E4: YES | F4: Filled | G4: GATE-WP001-01, GATE-WP002-01, GATE-WP004-01, GATE-WP005-01, GATE-WP006-01, GATE-WP009-01, GATE-WP020-01, GATE-WP023-01, GATE-WP025-01, GATE-WP028-01 | H4: Dated decisions and role-specific acceptance evidence | I4: Role exists; evidence gates still apply
A5: IRIS | B5: Supervisor and academic approver | C5: internal_human | D5: Iris | E5: YES | F5: Filled | G5: GATE-WP002-02, GATE-WP006-02, GATE-WP007-01, GATE-WP008-01, GATE-WP011-01, GATE-WP016-01, GATE-WP017-01, GATE-WP019-02, GATE-WP021-02, GATE-WP022-01, GATE-WP026-01, GATE-WP027-01, GATE-WP029-01 | H5: Dated decisions and role-specific acceptance evidence | I5: Role exists; evidence gates still apply
A6: ARNON | B6: Supervisor and academic approver | C6: internal_human | D6: Arnon | E6: YES | F6: Filled | G6: GATE-WP002-02, GATE-WP006-02, GATE-WP007-01, GATE-WP008-01, GATE-WP011-01, GATE-WP016-01, GATE-WP017-01, GATE-WP019-02, GATE-WP021-02, GATE-WP022-01, GATE-WP026-01, GATE-WP027-01, GATE-WP029-01 | H6: Dated decisions and role-specific acceptance evidence | I6: Role exists; evidence gates still apply
A7: ZOOM_REVIEWER_B | B7: Independent Hebrew-English call reviewer | C7: human_gate | E7: NO | F7: Unfilled human | G7: GATE-WP002-01 | H7: Name, acceptance, availability, and independent evidence return | I7: Mapped gates remain blocked
A8: ZOOM_ADJUDICATOR | B8: Bilingual call adjudicator | C8: human_gate | E8: NO | F8: Unfilled human | G8: GATE-WP002-01, GATE-WP003-01 | H8: Name, acceptance, availability, and independent evidence return | I8: Mapped gates remain blocked
A9: IRIS_ROLE_REVIEWER | B9: Adversarial rehearsal reviewer acting in the Iris role | C9: human_gate | E9: NO | F9: Unfilled human | G9: GATE-WP005-01 | H9: Name, acceptance, availability, and independent evidence return | I9: Mapped gates remain blocked
A10: ARNON_ROLE_REVIEWER | B10: Adversarial rehearsal reviewer acting in the Arnon role | C10: human_gate | E10: NO | F10: Unfilled human | G10: GATE-WP005-01 | H10: Name, acceptance, availability, and independent evidence return | I10: Mapped gates remain blocked
A11: REHEARSAL_RECORDER | B11: Rehearsal evidence recorder | C11: human_gate | E11: NO | F11: Unfilled human | G11: GATE-WP005-01 | H11: Name, acceptance, availability, and independent evidence return | I11: Mapped gates remain blocked
A12: DOMAIN_REVIEWER_1 | B12: Independent software-modeling reviewer 1 | C12: human_gate | E12: NO | F12: Unfilled human | G12: GATE-WP012-01, GATE-WP013-01 | H12: Name, acceptance, availability, and independent evidence return | I12: Mapped gates remain blocked
A13: DOMAIN_REVIEWER_2 | B13: Independent software-modeling reviewer 2 | C13: human_gate | E13: NO | F13: Unfilled human | G13: GATE-WP012-01, GATE-WP013-01 | H13: Name, acceptance, availability, and independent evidence return | I13: Mapped gates remain blocked
A14: LABEL_ADJUDICATOR | B14: Independent label adjudicator | C14: human_gate | E14: NO | F14: Unfilled human | G14: GATE-WP013-01, GATE-WP014-01 | H14: Name, acceptance, availability, and independent evidence return | I14: Mapped gates remain blocked
A15: METHODS_REVIEWER | B15: Statistics and methods reviewer | C15: human_gate | E15: NO | F15: Unfilled human | G15: GATE-WP014-01, GATE-WP018-01, GATE-WP020-01, GATE-WP021-02, GATE-WP022-01, GATE-WP024-01 | H15: Name, acceptance, availability, and independent evidence return | I15: Mapped gates remain blocked
A16: EXTERNAL_REPLICATION_OWNER | B16: Authorized Plan B replication owner or panel | C16: external_gate | E16: NO | F16: Unfilled external | G16: GATE-WP015-01, GATE-WP019-01, GATE-WP021-01 | H16: Written role acceptance and authoritative evidence | I16: Mapped gates remain blocked
A17: CLINICAL_OWNER | B17: Clinical use-case owner | C17: external_gate | E17: NO | F17: Unfilled external | G17: GATE-WP018-01 | H17: Written role acceptance and authoritative evidence | I17: Mapped gates remain blocked
A18: DATA_CUSTODIAN | B18: Data custodian and authorization owner | C18: external_gate | E18: NO | F18: Unfilled external | G18: GATE-WP018-01 | H18: Written role acceptance and authoritative evidence | I18: Mapped gates remain blocked
... A21: GRADUATE_COORDINATOR | B21: Authorized university process contact | C21: external_gate | E21: NO | F21: Unfilled external | G21: GATE-WP010-01, GATE-WP026-02, GATE-WP029-02 | H21: Written role acceptance and authoritative evidence | I21: Mapped gates remain blocked
A22: LOCAL_VALIDATOR | B22: Deterministic local artifact validator | C22: tool | D22: Local deterministic validation | E22: YES | F22: Tool available | G22: None | H22: Deterministic local validator output | I22: Role exists; evidence gates still apply

Sheet Schedule
A1: Canonical Dependency-Ordered Schedule
A2: Due values are real Excel dates with an explicit Asia/Jerusalem timezone column. Overdue is calculated from NOW(); working targets remain provisional where noted in source controls.
A3: Due (local) | B3: Timezone | C3: WP_ID | D3: Checkpoint | E3: Owner Roles | F3: Status | G3: Overdue | H3: Acceptance Evidence
A4: 46236.5 | B4: Asia/Jerusalem | C4: WP-001 | D4: Reconcile sources, hashes, segment coverage, and provenance | E4: ALI | F4: partial | G4: =IF(OR(F4="accepted",F4="accepted_ongoing",F4="accepted_after_correction",F4="superseded_approved",F4="not_applicable_approved"),"CLOSED",IF(A4<NOW(),"OVERDUE","ON TRACK")) -> OVERDUE | H4: AC-WP001-01 [pending] | AC-WP001-02 [pending]
A5: 46237.75 | B5: Asia/Jerusalem | C5: WP-002 | D5: Dual-review and adjudicate the complete bilingual Zoom record | E5: ALI, ZOOM_REVIEWER_B, ZOOM_ADJUDICATOR, IRIS, ARNON | F5: blocked | G5: =IF(OR(F5="accepted",F5="accepted_ongoing",F5="accepted_after_correction",F5="superseded_approved",F5="not_applicable_approved"),"CLOSED",IF(A5<NOW(),"OVERDUE","ON TRACK")) -> ON TRACK | H5: AC-WP002-01 [pending] | AC-WP002-02 [pending]
A6: 46238.417 | B6: Asia/Jerusalem | C6: WP-003 | D6: Regenerate the bilingual transcript, call report, and R-A-Q registers | E6: ALI | F6: blocked | G6: =IF(OR(F6="accepted",F6="accepted_ongoing",F6="accepted_after_correction",F6="superseded_approved",F6="not_applicable_approved"),"CLOSED",IF(A6<NOW(),"OVERDUE","ON TRACK")) -> ON TRACK | H6: AC-WP003-01 [pending] | AC-WP003-02 [pending]
A7: 46238.5 | B7: Asia/Jerusalem | C7: WP-004 | D7: Build the August 5 supervisor presentation package | E7: ALI | F7: partial | G7: =IF(OR(F7="accepted",F7="accepted_ongoing",F7="accepted_after_correction",F7="superseded_approved",F7="not_applicable_approved"),"CLOSED",IF(A7<NOW(),"OVERDUE","ON TRACK")) -> ON TRACK | H7: AC-WP004-01 [pending] | AC-WP004-02 [pending]
A8: 46238.625 | B8: Asia/Jerusalem | C8: WP-005 | D8: Render, inspect, and rehearse the exact presentation | E8: ALI, IRIS_ROLE_REVIEWER, ARNON_ROLE_REVIEWER, REHEARSAL_RECORDER | F8: blocked | G8: =IF(OR(F8="accepted",F8="accepted_ongoing",F8="accepted_after_correction",F8="superseded_approved",F8="not_applicable_approved"),"CLOSED",IF(A8<NOW(),"OVERDUE","ON TRACK")) -> ON TRACK | H8: AC-WP005-01 [pending] | AC-WP005-02 [pending]
A9: 46238.75 | B9: Asia/Jerusalem | C9: WP-006 | D9: Approve, deliver, and access-test the exact supervisor package | E9: ALI, IRIS, ARNON | F9: blocked | G9: =IF(OR(F9="accepted",F9="accepted_ongoing",F9="accepted_after_correction",F9="superseded_approved",F9="not_applicable_approved"),"CLOSED",IF(A9<NOW(),"OVERDUE","ON TRACK")) -> ON TRACK | H9: AC-WP006-01 [pending] | AC-WP006-02 [pending]
A10: 46239.417 | B10: Asia/Jerusalem | C10: WP-007 | D10: Obtain and read back August 5 supervisor decisions | E10: ALI, IRIS, ARNON | F10: planned | G10: =IF(OR(F10="accepted",F10="accepted_ongoing",F10="accepted_after_correction",F10="superseded_approved",F10="not_applicable_approved"),"CLOSED",IF(A10<NOW(),"OVERDUE","ON TRACK")) -> ON TRACK | H10: AC-WP007-01 [pending] | AC-WP007-02 [pending]
A11: 46240.417 | B11: Asia/Jerusalem | C11: WP-008 | D11: Issue minutes and propagate decisions within 24 hours | E11: ALI, IRIS, ARNON | F11: blocked | G11: =IF(OR(F11="accepted",F11="accepted_ongoing",F11="accepted_after_correction",F11="superseded_approved",F11="not_applicable_approved"),"CLOSED",IF(A11<NOW(),"OVERDUE","ON TRACK")) -> ON TRACK | H11: AC-WP008-01 [pending] | AC-WP008-02 [pending]
A12: 46246.75 | B12: Asia/Jerusalem | C12: WP-009 | D12: Execute and log the first literature searches and screening pass | E12: ALI | F12: partial | G12: =IF(OR(F12="accepted",F12="accepted_ongoing",F12="accepted_after_correction",F12="superseded_approved",F12="not_applicable_approved"),"CLOSED",IF(A12<NOW(),"OVERDUE","ON TRACK")) -> ON TRACK | H12: AC-WP009-01 [pending]
A13: 46246.75 | B13: Asia/Jerusalem | C13: WP-010 | D13: Deliver proposal v0.2, Clalit brief, Penina map, and process inquiries | E13: ALI, GRADUATE_COORDINATOR, CLINICAL_OWNER | F13: partial | G13: =IF(OR(F13="accepted",F13="accepted_ongoing",F13="accepted_after_correction",F13="superseded_approved",F13="not_applicable_approved"),"CLOSED",IF(A13<NOW(),"OVERDUE","ON TRACK")) -> ON TRACK | H13: AC-WP010-01 [pending] | AC-WP010-02 [pending]
A14: 46240.75 | B14: Asia/Jerusalem | C14: WP-011 | D14: Freeze the human-evidence protocol and supervisor decisions | E14: ALI, IRIS, ARNON, METHODS_REVIEWER | F14: blocked | G14: =IF(OR(F14="accepted",F14="accepted_ongoing",F14="accepted_after_correction",F14="superseded_approved",F14="not_applicable_approved"),"CLOSED",IF(A14<NOW(),"OVERDUE","ON TRACK")) -> ON TRACK | H14: AC-WP011-01 [pending] | AC-WP011-02 [pending]
A15: 46246.75 | B15: Asia/Jerusalem | C15: WP-012 | D15: Run EXP-019 independent reviewer calibration | E15: DOMAIN_REVIEWER_1, DOMAIN_REVIEWER_2, LABEL_ADJUDICATOR | F15: blocked | G15: =IF(OR(F15="accepted",F15="accepted_ongoing",F15="accepted_after_correction",F15="superseded_approved",F15="not_applicable_approved"),"CLOSED",IF(A15<NOW(),"OVERDUE","ON TRACK")) -> ON TRACK | H15: AC-WP012-01 [pending] | AC-WP012-02 [pending]
... A32: 46302.75 | B32: Asia/Jerusalem | C32: WP-029 | D32: Close authorized submission and issue the closure certificate | E32: ALI, IRIS, ARNON, GRADUATE_COORDINATOR | F32: blocked | G32: =IF(OR(F32="accepted",F32="accepted_ongoing",F32="accepted_after_correction",F32="superseded_approved",F32="not_applicable_approved"),"CLOSED",IF(A32<NOW(),"OVERDUE","ON TRACK")) -> ON TRACK | H32: AC-WP029-01 [pending] | AC-WP029-02 [pending]

Sheet Decision_Log
A1: August 5 Supervisor Decision Capture
A2: Silence is Defer. Retire or supersede is explicitly representable; written propagation evidence remains required.
A3: Decision_ID | B3: Decision Requested | C3: Priority | D3: Outcome | E3: Exact Correction/Rationale | F3: Approver | G3: Owner | H3: Written Deadline | I3: Affected Artifacts | J3: Propagation Status
A4: D-RQ-01 | B4: Umbrella RQ wording | C4: Mandatory | D4: Pending | F4: Iris and Arnon | I4: RQ pack; proposal; deck; master | J4: Not started
A5: D-RQ-02 | B5: SQ1-SQ3 wording | C5: Mandatory | D5: Pending | F5: Iris and Arnon | I5: RQ pack; proposal; deck; master | J5: Not started
A6: D-RQ-03 | B6: Three-study mapping and methods | C6: Mandatory | D6: Pending | F6: Iris and Arnon | I6: RQ pack; proposal; deck; master | J6: Not started
A7: D-RQ-04 | B7: Plan A conditional medical / Plan B non-medical | C7: Mandatory | D7: Pending | F7: Iris and Arnon | I7: RQ pack; proposal; deck; master | J7: Not started
A8: D-RQ-05 | B8: Every RQ answerable under Plan B | C8: Mandatory | D8: Pending | F8: Iris and Arnon | I8: RQ pack; proposal; deck; master | J8: Not started
A9: D-RQ-06 | B9: August 26 medical fallback trigger | C9: Mandatory | D9: Pending | F9: Iris and Arnon | I9: RQ pack; proposal; deck; master | J9: Not started
A10: D-RQ-07 | B10: Evidence boundary and five claim states | C10: Mandatory | D10: Pending | F10: Iris and Arnon | I10: RQ pack; proposal; deck; master | J10: Not started
A11: D-RQ-08 | B11: Literature scope and taxonomy | C11: Time permitting | D11: Pending | F11: Iris and Arnon | I11: RQ pack; proposal; deck; master | J11: Not started
A12: D-RQ-09 | B12: MIMIC metadata-only boundary | C12: Time permitting | D12: Pending | F12: Iris and Arnon | I12: RQ pack; proposal; deck; master | J12: Not started
A13: D-RQ-10 | B13: Medical and university-process owners | C13: Assignment | D13: Pending | F13: Iris and Arnon | I13: RQ pack; proposal; deck; master | J13: Not started

Sheet Human_Review
A1: July 29 Zoom Human Review — Operational Batches
A2: Chronological PRI/REM ranges cover S-0001 through S-1195 exactly once. Calibration and full-media rows are separate evidence controls.
A3: Batch_ID | B3: Segment Range | C3: Segment Count | D3: Purpose | E3: Reviewer A | F3: Reviewer B | G3: Adjudicator | H3: Status | I3: Due | J3: Overdue | K3: Completion Evidence
A4: CAL-01 | B4: 30 balanced sample rows | C4: 30 | D4: Codebook/format calibration only; no shared substantive answers | E4: Ali | H4: Not started | I4: 46236.5 | J4: =IF(OR(H4="Reviewer complete",H4="Adjudicated"),"CLOSED",IF(I4<NOW(),"OVERDUE","ON TRACK")) -> OVERDUE | K4: Two blind sample returns + frozen codebook
A5: PRI-01 | B5: S-0053-S-0126 | C5: 74 | D5: Candidacy outcomes and follow-up examination | E5: Ali | H5: Not started | I5: 46238.5 | J5: =IF(OR(H5="Reviewer complete",H5="Adjudicated"),"CLOSED",IF(I5<NOW(),"OVERDUE","ON TRACK")) -> ON TRACK | K5: Both reviewer rows
A6: PRI-02 | B6: S-0150-S-0185 | C6: 36 | D6: Milestones and reported availability | E6: Ali | H6: Not started | I6: 46238.5 | J6: =IF(OR(H6="Reviewer complete",H6="Adjudicated"),"CLOSED",IF(I6<NOW(),"OVERDUE","ON TRACK")) -> ON TRACK | K6: Both reviewer rows
A7: PRI-03 | B7: S-0891-S-0972 | C7: 82 | D7: Medical assertions and MIMIC organization | E7: Ali | H7: Not started | I7: 46238.5 | J7: =IF(OR(H7="Reviewer complete",H7="Adjudicated"),"CLOSED",IF(I7<NOW(),"OVERDUE","ON TRACK")) -> ON TRACK | K7: Both reviewer rows
A8: PRI-04 | B8: S-1058-S-1152 | C8: 95 | D8: Partner meeting, access terminology, and retrieval | E8: Ali | H8: Not started | I8: 46238.5 | J8: =IF(OR(H8="Reviewer complete",H8="Adjudicated"),"CLOSED",IF(I8<NOW(),"OVERDUE","ON TRACK")) -> ON TRACK | K8: Both reviewer rows
A9: REM-01 | B9: S-0001-S-0052 | C9: 52 | D9: Remaining chronological review | E9: Ali | H9: Not started | I9: 46243.5 | J9: =IF(OR(H9="Reviewer complete",H9="Adjudicated"),"CLOSED",IF(I9<NOW(),"OVERDUE","ON TRACK")) -> ON TRACK | K9: Both reviewer rows
A10: REM-02 | B10: S-0127-S-0149 | C10: 23 | D10: Remaining chronological review | E10: Ali | H10: Not started | I10: 46243.5 | J10: =IF(OR(H10="Reviewer complete",H10="Adjudicated"),"CLOSED",IF(I10<NOW(),"OVERDUE","ON TRACK")) -> ON TRACK | K10: Both reviewer rows
A11: REM-03 | B11: S-0186-S-0285 | C11: 100 | D11: Remaining chronological review | E11: Ali | H11: Not started | I11: 46243.5 | J11: =IF(OR(H11="Reviewer complete",H11="Adjudicated"),"CLOSED",IF(I11<NOW(),"OVERDUE","ON TRACK")) -> ON TRACK | K11: Both reviewer rows
A12: REM-04 | B12: S-0286-S-0385 | C12: 100 | D12: Remaining chronological review | E12: Ali | H12: Not started | I12: 46243.5 | J12: =IF(OR(H12="Reviewer complete",H12="Adjudicated"),"CLOSED",IF(I12<NOW(),"OVERDUE","ON TRACK")) -> ON TRACK | K12: Both reviewer rows
A13: REM-05 | B13: S-0386-S-0485 | C13: 100 | D13: Remaining chronological review | E13: Ali | H13: Not started | I13: 46243.5 | J13: =IF(OR(H13="Reviewer complete",H13="Adjudicated"),"CLOSED",IF(I13<NOW(),"OVERDUE","ON TRACK")) -> ON TRACK | K13: Both reviewer rows
A14: REM-06 | B14: S-0486-S-0585 | C14: 100 | D14: Remaining chronological review | E14: Ali | H14: Not started | I14: 46243.5 | J14: =IF(OR(H14="Reviewer complete",H14="Adjudicated"),"CLOSED",IF(I14<NOW(),"OVERDUE","ON TRACK")) -> ON TRACK | K14: Both reviewer rows
A15: REM-07 | B15: S-0586-S-0685 | C15: 100 | D15: Remaining chronological review | E15: Ali | H15: Not started | I15: 46243.5 | J15: =IF(OR(H15="Reviewer complete",H15="Adjudicated"),"CLOSED",IF(I15<NOW(),"OVERDUE","ON TRACK")) -> ON TRACK | K15: Both reviewer rows
... A21: MEDIA-A | B21: Full 46:26.283 media | C21: 1 | D21: Reviewer A full-media evidence including ASR edges | E21: Ali | H21: Not started | I21: 46243.5 | J21: =IF(OR(H21="Reviewer complete",H21="Adjudicated"),"CLOSED",IF(I21<NOW(),"OVERDUE","ON TRACK")) -> ON TRACK | K21: MEDIA-TIMELINE row
A22: MEDIA-B | B22: Full 46:26.283 media | C22: 1 | D22: Reviewer B full-media evidence including ASR edges | H22: Not started | I22: 46243.5 | J22: =IF(OR(H22="Reviewer complete",H22="Adjudicated"),"CLOSED",IF(I22<NOW(),"OVERDUE","ON TRACK")) -> ON TRACK | K22: MEDIA-TIMELINE row
A23: ADJ-01 | B23: All mechanical disagreements | D23: Third-person adjudication | H23: Not started | I23: 46245.5 | J23: =IF(OR(H23="Reviewer complete",H23="Adjudicated"),"CLOSED",IF(I23<NOW(),"OVERDUE","ON TRACK")) -> ON TRACK | K23: One adjudication per disagreement
A24: MERGE-01 | B24: S-0001-S-1195 | C24: 1195 | D24: Deterministic final merge and provenance | H24: Not started | I24: 46246.5 | J24: =IF(OR(H24="Reviewer complete",H24="Adjudicated"),"CLOSED",IF(I24<NOW(),"OVERDUE","ON TRACK")) -> ON TRACK | K24: CSV/JSON; readiness checks; hashes

Sheet Literature_Search
A1: Literature Search Execution Register — Protocol Ready, Not Run
A2: Rows are generated from the tracked QL-01 through QL-05 execution register. Blank dates/counts are evidence-honest, not missing generated data.
A3: Query_ID | B3: Concept | C3: Frozen Boolean Query | D3: Database | E3: Field/Filter Handling | F3: Status | G3: Search Date | H3: Returned | I3: Included | J3: SQ/Study Mapping | K3: Evidence/Access Note
A4: QL-01 | B4: Agentic or multi-agent AI with human oversight | C4: ("agentic AI" OR "AI agent" OR "AI agents" OR "multi-agent system" OR "multi-agent systems" OR "multiagent system" OR "multiagent systems") AND ("human oversight" OR "human-in-the-loop" OR "human in the loop" OR "human-on-the-loop" OR "human on the loop" OR "human intervention" OR "expert review") | D4: ACM Digital Library | E4: Title/abstract/keywords where supported; 2015-2026 | F4: Protocol ready / not run | J4: SQ1, Study 1, intervention architecture and authority. | K4: No count or coverage claim until executed
A5: QL-01 | B5: Agentic or multi-agent AI with human oversight | C5: ("agentic AI" OR "AI agent" OR "AI agents" OR "multi-agent system" OR "multi-agent systems" OR "multiagent system" OR "multiagent systems") AND ("human oversight" OR "human-in-the-loop" OR "human in the loop" OR "human-on-the-loop" OR "human on the loop" OR "human intervention" OR "expert review") | D5: IEEE Xplore | E5: Metadata/abstract/index terms where supported; 2015-2026 | F5: Protocol ready / not run | J5: SQ1, Study 1, intervention architecture and authority. | K5: No count or coverage claim until executed
A6: QL-01 | B6: Agentic or multi-agent AI with human oversight | C6: ("agentic AI" OR "AI agent" OR "AI agents" OR "multi-agent system" OR "multi-agent systems" OR "multiagent system" OR "multiagent systems") AND ("human oversight" OR "human-in-the-loop" OR "human in the loop" OR "human-on-the-loop" OR "human on the loop" OR "human intervention" OR "expert review") | D6: Scopus | E6: TITLE-ABS-KEY; 2015-2026 | F6: Protocol ready / not run | J6: SQ1, Study 1, intervention architecture and authority. | K6: No count or coverage claim until executed
A7: QL-01 | B7: Agentic or multi-agent AI with human oversight | C7: ("agentic AI" OR "AI agent" OR "AI agents" OR "multi-agent system" OR "multi-agent systems" OR "multiagent system" OR "multiagent systems") AND ("human oversight" OR "human-in-the-loop" OR "human in the loop" OR "human-on-the-loop" OR "human on the loop" OR "human intervention" OR "expert review") | D7: Web of Science | E7: Topic field; 2015-2026 | F7: Protocol ready / not run | J7: SQ1, Study 1, intervention architecture and authority. | K7: No count or coverage claim until executed
A8: QL-02 | B8: Expert feedback, knowledge capture, memory, and reusable judgment | C8: ("expert feedback" OR "human feedback" OR "expert judgment" OR "expert judgements" OR "human judgment" OR "human judgements") AND ("knowledge capture" OR "knowledge reuse" OR "judgment reuse" OR "judgement reuse" OR memory OR provenance OR reconciliation) AND (AI OR "artificial intelligence" OR agent OR agents) | D8: ACM Digital Library | E8: Title/abstract/keywords where supported; 2015-2026 | F8: Protocol ready / not run | J8: SQ2, Study 2, governed judgment lifecycle. | K8: No count or coverage claim until executed
A9: QL-02 | B9: Expert feedback, knowledge capture, memory, and reusable judgment | C9: ("expert feedback" OR "human feedback" OR "expert judgment" OR "expert judgements" OR "human judgment" OR "human judgements") AND ("knowledge capture" OR "knowledge reuse" OR "judgment reuse" OR "judgement reuse" OR memory OR provenance OR reconciliation) AND (AI OR "artificial intelligence" OR agent OR agents) | D9: IEEE Xplore | E9: Metadata/abstract/index terms where supported; 2015-2026 | F9: Protocol ready / not run | J9: SQ2, Study 2, governed judgment lifecycle. | K9: No count or coverage claim until executed
